<?xml version='1.0'?>
<robot xmlns:xacro="http://www.ros.org/wiki/xacro"
 	xmlns:sensor="http://playerstage.sourceforge.net/gazebo/xmlschema/#sensor"
    	xmlns:controller="http://playerstage.sourceforge.net/gazebo/xmlschema/#controller"
    	xmlns:interface="http://playerstage.sourceforge.net/gazebo/xmlschema/#interface"
	name="dd_robot">

<!-- Future Variables -->
		<!-- Length of Body -->
		<!-- Width of Body -->
		<!-- Height of Body -->

		<!-- Radius of Wheels -->
		<!-- Length of Wheels -->
    <xacro:property name="length_wheel" value=".0635" />
    <xacro:property name="radius_wheel" value=".10795" />

    <xacro:macro name="default_inertial" params="mass">
             <inertial>
                     <mass value="${mass}" />
                     <inertia ixx="1.0" ixy="0.0" ixz="0.0"
                              iyy="1.0" iyz="0.0"
                              izz="1.0" />
             </inertial>
    </xacro:macro>



		<!-- Locations -->


	<!-- Base Link -->

	<link name="base_link">
		<visual>
			<origin xyz="0 0 0" rpy="0 0 0" />
			<geometry>
				<box size=".4699 .3302 0.1016"/>
			</geometry>
      <material name="black"/>
		</visual>

		<collision>
			<origin xyz="0 0 0" rpy="0 0 0"/>
			<geometry>
				<box size = ".5 .4 .2"/>
			</geometry>

		</collision>


    <xacro:default_inertial mass="7.71"/>



	</link>



	<!-- r_fwheel (Right Front Wheel) -->

	<joint name="joint_r_fwheel" type= "continuous">
		<parent link="base_link"/>
		<child link="r_fwheel"/>
		<origin xyz=".14605 -.19685 0" rpy="0 0 0" />
		<axis xyz="0 1 0" />
	</joint>
  <link name= "r_fwheel">
    <visual>
      <origin xyz="0 0 0" rpy="1.5707 0 0" />
        <geometry>
          <cylinder length ="0.0635" radius="0.10795"/>
        </geometry>
    </visual>

    <collision>
      <origin xyz="0 0 0" rpy="1.5707 0 0"/>
      <geometry>
        <cylinder length ="0.0635" radius="0.10795"/>
      </geometry>
    </collision>


    <xacro:default_inertial mass="1"/>

  </link>



<!-- r_bwheel (Right Back Wheel) -->

	<joint name="joint_r_bwheel" type= "continuous">
		<parent link="base_link"/>
		<child link="r_bwheel"/>
		<origin xyz="-.14605 -.19685 0" rpy="0 0 0" />
		<axis xyz="0 1 0" />
	</joint>
  <link name= "r_bwheel">
      <visual>
      <origin xyz="0 0 0" rpy="1.5707 0 0" />
          <geometry>
              <cylinder length ="0.0635" radius="0.10795"/>
          </geometry>
    </visual>

      <collision>
      <origin xyz="0 0 0" rpy="1.5707 0 0"/>
      <geometry>
        <cylinder length ="0.0635" radius="0.10795"/>
      </geometry>
    </collision>

    <xacro:default_inertial mass="1"/>


  </link>



	<!-- l_fwheel (Left Front Wheel) -->

	<joint name="joint_l_fwheel" type= "continuous">

		<parent link="base_link"/>
		<child link="l_fwheel"/>
		<origin xyz=".14605 .19685 0" rpy="0 0 0" />
		<axis xyz="0 1 0" />
	</joint>
  <link name= "l_fwheel">
    	<visual>
			<origin xyz="0 0 0" rpy="1.5707 0 0" />
        	<geometry>
            	<cylinder length ="0.0635" radius="0.10795"/>
          </geometry>
		</visual>

			<collision>
				<origin xyz="0 0 0" rpy="1.5707 0 0"/>
				<geometry>
					<cylinder length ="0.0635" radius="0.10795"/>
				</geometry>
			</collision>

      <xacro:default_inertial mass="1"/>


	</link>



	<!-- l_bwheel (Left Back Wheel) -->

	<joint name="joint_l_bwheel" type= "continuous">
		<parent link="base_link"/>
		<child link="l_bwheel"/>
		<origin xyz="-.14605 .19685 0" rpy="0 0 0" />
		<axis xyz="0 1 0" />
	</joint>
  <link name= "l_bwheel">
    <visual>
			<origin xyz="0 0 0" rpy="1.5707 0 0" />
        	<geometry>
            	<cylinder length ="0.0635" radius="0.10795"/>
          </geometry>
		</visual>

			<collision>
				<origin xyz="0 0 0" rpy="1.5707 0 0"/>
				<geometry>
					<cylinder length ="0.0635" radius="0.10795"/>
				</geometry>
			</collision>

    <xacro:default_inertial mass="1"/>
    <inertial>
      <origin xyz="0 0 0" rpy="0 0 0"/>
    </inertial>

	</link>




	<!-- Camera joint -->
	  <joint name="camera_joint" type="fixed">
	    <axis xyz="0 1 0" />
	    <origin xyz="0.125 0 0.05" rpy="0 0 0"/>
	    <parent link="base_link"/>
	    <child link="camera_link"/>
	  </joint>

	  <!-- Camera -->
	  <link name="camera_link">
	    <collision>
	      <origin xyz="0 0 0" rpy="0 0 0"/>
	      <geometry>
  		<box size="0.05 0.05 0.05"/>
  	      </geometry>
  	    </collision>

  	    <visual>
  	      <origin xyz="0 0 0" rpy="0 0 0"/>
  	      <geometry>
  		<box size="0.05 0.05 0.05"/>
  	      </geometry>
  	      <material name="red">
  		<color rgba="1 0 0 1"/>
  	      </material>
  	    </visual>

  	    <inertial>
  	      <mass value="1e-5" />
  	      <origin xyz="0 0 0" rpy="0 0 0"/>
  	      <inertia ixx="1e-6" ixy="0" ixz="0" iyy="1e-6" iyz="0" izz="1e-6" />
  	    </inertial>
	  </link>



	  <!-- Hokuyo joint -->
	  <joint name="hokuyo_joint" type="fixed">
	    <origin xyz="0.125 0.05 0.15" rpy="0 0 0"/>
	    <parent link="base_link"/>
	    <axis xyz="0 1 0" />
	    <child link="hokuyo_link"/>
	  </joint>

	  <!-- Hokuyo Laser -->
	  <link name="hokuyo_link">
  	    <collision>
  	      <origin xyz="0 0 0" rpy="0 0 0"/>
  	      <geometry>
  		<box size="0.1 0.1 0.1"/>
  	      </geometry>
  	    </collision>

  	    <visual>
  	      <origin xyz="0 0 0" rpy="0 0 0"/>
  	      <geometry>
  	        <mesh filename="package://ros_robotics/sensors/hokuyo.dae"/>
  	      </geometry>
  	    </visual>

  	    <inertial>
  	      <mass value="1e-5" />
  	      <origin xyz="0 0 0" rpy="0 0 0"/>
  	      <inertia ixx="1e-6" ixy="0" ixz="0" iyy="1e-6" iyz="0" izz="1e-6" />
  	    </inertial>
	  </link>

<!-- GAZEBO ADDITIONS -->


	<gazebo reference="base_link">
		<material>Gazebo/DarkGrey</material>
	</gazebo>

<gazebo>
  <plugin name="skid_steer_drive_controller" filename="libgazebo_ros_skid_steer_drive.so">
    <updateRate>100.0</updateRate>
    <robotNamespace>/</robotNamespace>
    <leftFrontJoint>joint_l_fwheel</leftFrontJoint>
    <rightFrontJoint>joint_r_fwheel</rightFrontJoint>
    <leftRearJoint>joint_l_bwheel</leftRearJoint>
    <rightRearJoint>joint_r_bwheel</rightRearJoint>
    <wheelSeparation>.3556</wheelSeparation>
    <wheelDiameter>0.2159</wheelDiameter>
    <robotBaseFrame>base_link</robotBaseFrame>
    <torque>1</torque>
    <topicName>cmd_vel</topicName>
    <broadcastTF>1</broadcastTF>
  </plugin>
</gazebo>


<!-- Gazebo plugin for ROS control -->
<gazebo>
		<plugin name="gazebo_ros_control"
			filename="libgazebo_ros_control.so">
			<robotNamespace>/dd_robot</robotNamespace>
		</plugin>
</gazebo>

<!-- camera_link -->
 <gazebo reference="camera_link">
	 <mu1>0.2</mu1>
	 <mu2>0.2</mu2>
	 <material>Gazebo/Red</material>
 </gazebo>

 <!-- hokuyo -->
 <gazebo reference="hokuyo_link">
	 <sensor type="ray" name="head_hokuyo_sensor">
		 <pose>0 0 0 0 0 0</pose>
		 <visualize>false</visualize>
		 <update_rate>40</update_rate>
		 <ray>
			 <scan>
				 <horizontal>
					 <samples>720</samples>
					 <resolution>1</resolution>
					 <min_angle>-1.570796</min_angle>
					 <max_angle>1.570796</max_angle>
				 </horizontal>
			 </scan>
			 <range>
				 <min>0.10</min>
				 <max>30.0</max>
				 <resolution>0.01</resolution>
			 </range>
			 <noise>
				 <type>gaussian</type>
				 <!-- Noise parameters based on published spec for Hokuyo laser
							achieving "+-30mm" accuracy at range < 10m.  A mean of 0.0m and
							stddev of 0.01m will put 99.7% of samples within 0.03m of the true
							reading. -->
				 <mean>0.0</mean>
				 <stddev>0.01</stddev>
			 </noise>
		 </ray>
		 <plugin name="gazebo_ros_head_hokuyo_controller" filename="libgazebo_ros_laser.so">
			 <topicName>/robot/laser/scan</topicName>
			 <frameName>hokuyo_link</frameName>
		 </plugin>
	 </sensor>
 </gazebo>

 <!-- camera -->
 <gazebo reference="camera_link">
	 <sensor type="camera" name="camera1">
		 <update_rate>30.0</update_rate>
		 <camera name="head">
			 <horizontal_fov>1.3962634</horizontal_fov>
			 <image>
				 <width>800</width>
				 <height>800</height>
				 <format>R8G8B8</format>
			 </image>
			 <clip>
				 <near>0.02</near>
				 <far>300</far>
			 </clip>
			 <noise>
				 <type>gaussian</type>
				 <!-- Noise is sampled independently per pixel on each frame.
							That pixel's noise value is added to each of its color
							channels, which at that point lie in the range [0,1]. -->
				 <mean>0.0</mean>
				 <stddev>0.007</stddev>
			 </noise>
		 </camera>
		 <plugin name="camera_controller" filename="libgazebo_ros_camera.so">
			 <alwaysOn>true</alwaysOn>
			 <updateRate>0.0</updateRate>
			 <cameraName>robot/camera1</cameraName>
			 <imageTopicName>image_raw</imageTopicName>
			 <cameraInfoTopicName>camera_info</cameraInfoTopicName>
			 <frameName>camera_link</frameName>
			 <hackBaseline>0.07</hackBaseline>
			 <distortionK1>0.0</distortionK1>
			 <distortionK2>0.0</distortionK2>
			 <distortionK3>0.0</distortionK3>
			 <distortionT1>0.0</distortionT1>
			 <distortionT2>0.0</distortionT2>
		 </plugin>
	 </sensor>
 </gazebo>



<!-- IMU Sensor -->

<!-- IMU -->
<link name="imu_link">
  <inertial>
    <mass value="0.001"/>
    <origin rpy="0 0 0" xyz="0 0 0"/>
    <inertia ixx="0.0001" ixy="0" ixz="0" iyy="0.0001" iyz="0" izz="0.0001"/>
  </inertial>

  <visual>
    <origin rpy="0 0 0" xyz="0 0 0"/>
    <geometry>
      <box size="0.1 0.1 0.1"/>
    </geometry>
  </visual>

  <collision>
    <origin rpy="0 0 0" xyz="0 0 0"/>
    <geometry>
      <box size="0.1 0.1 0.1"/>
    </geometry>
  </collision>
</link>

<!-- IMU Joint -->
  <joint name="imu_joint" type="fixed">
    <axis xyz="1 0 0"/> <!-- 0 1 0 -->
    <origin xyz="0 0 0.28"/>
    <parent link="base_link"/>
    <child link="imu_link"/>
  </joint>

<gazebo>
    <plugin name="imu_plugin" filename="libhector_gazebo_ros_imu.so">
          <updateRate>1000</updateRate>
          <bodyName>base_link</bodyName>
          <topicName>/imu</topicName>
          <serviceName>/imu/calibrate</serviceName>
          <accelOffset>0.0 0.0 0.0</accelOffset>
          <accelDrift>0.0 0.0 0.0</accelDrift>
          <accelDriftFrequency>0.0 0.0 0.0</accelDriftFrequency>
          <accelGaussianNoise>0.0 0.0 0.0</accelGaussianNoise>
          <rateOffset>0.0 0.0 0.0</rateOffset>
          <rateDrift>0.0 0.0 0.0</rateDrift>
          <rateDriftFrequency>0.0 0.0 0.0</rateDriftFrequency>
          <rateGaussianNoise>0.0 0.0 0.0</rateGaussianNoise>
          <headingOffset>0.0</headingOffset>
          <headingDrift>0.0</headingDrift>
          <headingDriftFrequency>0.0</headingDriftFrequency>
          <headingGaussianNoise>0.0</headingGaussianNoise>
          <rpyOffset>0.0 0.0 0.0</rpyOffset>
          <xyzOffset>0.0 0.0 0.0</xyzOffset>
          <gaussianNoise>0.0</gaussianNoise>
      </plugin>
  </gazebo>




 <!-- GPS Sensor -->
 <gazebo>
   <plugin name="novatel_gps_sim" filename="libhector_gazebo_ros_gps.so">
     <alwaysOn>1</alwaysOn>
     <updateRate>10.0</updateRate>
     <bodyName>base_link</bodyName>
     <topicName>fix</topicName>
     <velocityTopicName>fix_velocity</velocityTopicName>
     <drift>5.0 5.0 5.0</drift>
     <gaussianNoise>0.1 0.1 0.1</gaussianNoise>
     <velocityDrift>0 0 0</velocityDrift>
     <velocityGaussianNoise>0.1 0.1 0.1</velocityGaussianNoise>
   </plugin>
 </gazebo>





</robot>
